<?xml version="1.0" ?>
<!-- inertial values taken from solidworks model with appropriate model materials -->

<robot name="turtlebot3_waffle_pi"
  xmlns:xacro="http://ros.org/wiki/xacro">
  <!--
  params from
    package://interbotix_xsarm_descriptions/launch/xsarm_description.launch
    package://interbotix_xsarm_moveit/launch/xsarm_moveit.launch
  -->
  <xacro:arg name="robot_name" default = "asdf"/>
  <xacro:arg name="arm_model" default = "wx250s"/>
  <xacro:arg name="base_link_frame" default="arm_base_link"/> <!-- modify xsarm_description urdf-->
  <xacro:arg name="update_rate" default="15.0"/>
  <xacro:arg name="arm" default="true"/> <!-- parameter to include the arm joint. -->
  <xacro:property name="use_arm" value="$(arg arm)"/>


  <xacro:include filename="$(find arlo_gazebo_description)/urdf/common_properties.xacro"/>
  <xacro:include filename="$(find arlo_gazebo_description)/urdf/turtlebot3_waffle_pi.gazebo.xacro"/>

  <link name="$(arg robot_name)/base_footprint"/>

  <joint name="base_joint" type="fixed">
    <parent link="$(arg robot_name)/base_footprint"/>
    <child link="$(arg robot_name)/base_link" />
    <origin xyz="0 0 0.0265" rpy="0 0 0"/>
    <!-- <origin xyz="0 0 " rpy="0 0 0"/> -->
  </joint>

  <link name="$(arg robot_name)/base_link">
    <origin xyz="0 0 0.0265" rpy="0 0 0"/>
    <visual>
      <geometry>
        <mesh filename="package://arlo_gazebo_description/meshes/bases/arlo2.stl" scale="1.0 1.0 1.0"/>
      </geometry>
      <material name="light_black"/>
    </visual>

    <collision>
      <geometry>
        <mesh filename="package://arlo_gazebo_description/meshes/bases/arlo2.stl" scale="1.0 1.0 1.0"/>
      </geometry>
    </collision>

    <inertial>
      <mass value="10.210121"/>
      <origin xyz=" -6.1671e-3 -5.6233e-4 7.052935e-2"/>
      <inertia ixx="0.12463087" ixy="0.00007141" ixz="0.00162718" iyy="0.0917392" iyz="0.00013135" izz="0.13717304" />
    </inertial>
  </link>

  <xacro:if value="$(arg arm)">
    <joint name="arm_base_joint" type="fixed">
      <parent link="$(arg robot_name)/base_link"/>
      <child link="$(arg robot_name)/$(arg base_link_frame)" />
      <origin xyz="0.05 0 0.222" rpy="0 0 0"/>
    </joint>
  </xacro:if>
  
  <joint name="wheel_left_joint" type="continuous">
    <parent link="$(arg robot_name)/base_link"/>
    <child link="$(arg robot_name)/wheel_left_link"/>
    <origin xyz="0.0 0.19397 0.05012" rpy="-1.57 0 0"/>
    <axis xyz="0 0 1"/>
  </joint>

  <transmission name="trans_wheel_left_joint">
    <type>transmission_interface/SimpleTransmission</type>
    <joint name="wheel_left_joint">
      <hardwareInterface>hardware_interface/EffortJointInterface</hardwareInterface>
    </joint>
    <actuator name="wheel_left_joint_motor">
      <mechanicalReduction>1</mechanicalReduction>
    </actuator>
  </transmission>

  <link name="$(arg robot_name)/wheel_left_link">
    <visual>
      <origin xyz="0 0 0" rpy="1.57 0 0"/>
      <geometry>
        <mesh filename="package://arlo_gazebo_description/meshes/wheels/myleft.stl" scale="1 1 1"/>
      </geometry>
      <material name="dark"/>
    </visual>

    <collision>
      <origin xyz="0 0 0" rpy="1.57 0 0"/>
      <!-- <origin xyz="0 0 0" rpy="0 0 0"/> -->
      <geometry>
        <mesh filename="package://arlo_gazebo_description/meshes/wheels/myright.stl" scale="1 1 1"/>
        <!-- <cylinder length="0.018" radius="0.0762"/> -->
      </geometry>
    </collision>

    <inertial>
      <origin xyz="0 0 0" />
      <mass value="0.10198895" />
      <inertia ixx="0.00014346" ixy="0" ixz="0" iyy="0.00027204" iyz="0" izz="0.00014283" />
      <!-- <inertia ixx="1.5e-6" ixy="0" ixz="0" iyy="3.0e-6" iyz="0" izz="1.5e-6" /> -->
    </inertial>
  </link>
  <!-- right wheel -->
  <joint name="wheel_right_joint" type="continuous">
    <parent link="$(arg robot_name)/base_link"/>
    <child link="$(arg robot_name)/wheel_right_link"/>
    <origin xyz="0.0 -0.19397 0.05012" rpy="-1.57 0 0"/>
    <axis xyz="0 0 1"/>
  </joint>

  <transmission name="trans_wheel_right_joint">
    <type>transmission_interface/SimpleTransmission</type>
    <joint name="wheel_right_joint">
      <hardwareInterface>hardware_interface/EffortJointInterface</hardwareInterface>
    </joint>
    <actuator name="wheel_right_joint_motor">
      <mechanicalReduction>1</mechanicalReduction>
    </actuator>
  </transmission>

  <link name="$(arg robot_name)/wheel_right_link">
    <visual>
      <origin xyz="0 0 0" rpy="1.57 0 0"/>
      <!-- <origin xyz="0 0 0" rpy="0 0 0"/> -->
      <geometry>
        <!-- <cylinder lensgth="0.018" radius="0.0763"/> -->
        <mesh filename="package://arlo_gazebo_description/meshes/wheels/myright.stl" scale="1 1 1"/>
      </geometry>
      <material name="dark"/>
    </visual>

    <collision>
      <origin xyz="0 0 0" rpy="1.57 0 0"/>
      <!-- <origin xyz="0 0 0" rpy="0 0 0"/> -->
      <geometry>
        <mesh filename="package://arlo_gazebo_description/meshes/wheels/myright.stl" scale="1 1 1"/>
        <!-- <cylinder length="0.018" radius="0.0763"/> -->
      </geometry>
    </collision>

    <inertial>
      <origin xyz="0 0 0" />
      <mass value="0.10198895" />
      <inertia ixx="0.00014346" ixy="0" ixz="0" iyy="0.00027204" iyz="0" izz="0.00014283" />
    </inertial>
  </link>
  <!-- castor_wheels -->
  <joint name="caster_front_joint" type="fixed">
    <origin rpy="-${3.14159265/2} 0 0" xyz="0.18522 0.0 0.0"/>
    <parent link="$(arg robot_name)/base_link"/>
    <child link="$(arg robot_name)/caster_front_link"/>
  </joint>

  <link name="$(arg robot_name)/caster_front_link">
    <visual>
      <origin xyz="0 0 0" rpy="0 0 0"/>
      <geometry>
        <cylinder length="0.0176" radius="0.0255"/>
      </geometry>
      <material name="light_black"/>
    </visual>
    <collision>
      <origin rpy="0 0 0" xyz="0 0 0"/>
      <geometry>
        <cylinder length="0.0176" radius="0.0255"/>
      </geometry>
    </collision>

    <inertial>
      <origin xyz="0 0 0"/>
      <mass value="0.01"/>
      <inertia ixx="1e-5" ixy="0.0" ixz="0.0" iyy="1e-5" iyz="0.0" izz="1e-5"/>
    </inertial>
  </link>

  <joint name="caster_back_joint" type="fixed">
    <origin rpy="-${3.14159265/2} 0 0" xyz="-0.18522 0.0 0.0"/>
    <parent link="$(arg robot_name)/base_link"/>
    <child link="$(arg robot_name)/caster_back_link"/>
  </joint>

  <link name="$(arg robot_name)/caster_back_link">
    <visual>
      <origin xyz="0 0 0" rpy="0 0 0"/>
      <geometry>
        <cylinder length="0.0176" radius="0.0255"/>
      </geometry>
      <material name="light_black"/>
    </visual>
    <collision>
      <origin rpy="0 0 0" xyz="0 0 0"/>
      <geometry>
        <cylinder length="0.0176" radius="0.0255"/>
      </geometry>
    </collision>
    <inertial>
      <origin xyz="0 0 0"/>
      <mass value="0.01"/>
      <inertia ixx="1e-5" ixy="0.0" ixz="0.0" iyy="1e-5" iyz="0.0" izz="1e-5"/>
    </inertial>
  </link>

  <joint name="imu_joint" type="fixed">
    <parent link="$(arg robot_name)/base_link"/>
    <child link="$(arg robot_name)/imu_link"/>
    <origin xyz="0.0 0 0.068" rpy="0 0 0"/>
  </joint>

  <link name="$(arg robot_name)/imu_link"/>

  <joint name="scan_joint" type="fixed">
    <parent link="$(arg robot_name)/base_link"/>
    <child link="$(arg robot_name)/base_scan"/>
    <origin xyz="0 0 0.18" rpy="${3.14159265} 0 0"/>
  </joint>

  <link name="$(arg robot_name)/base_scan">
    <visual>
      <origin xyz="0 0 0.0" rpy="0 0 0"/>
      <geometry>
        <mesh filename="package://arlo_gazebo_description/meshes/sensors/lds.stl" scale="0.001 0.001 0.001"/>
      </geometry>
      <material name="dark"/>
    </visual>

    <collision>
      <origin xyz="0.015 0 -0.0065" rpy="0 0 0"/>
      <geometry>
        <cylinder length="0.0315" radius="0.055"/>
      </geometry>
    </collision>

    <inertial>
      <mass value="0.114" />
      <origin xyz="0 0 0" />
      <inertia ixx="0.001" ixy="0.0" ixz="0.0" iyy="0.001" iyz="0.0" izz="0.001" />
    </inertial>
  </link>


  <link name="$(arg robot_name)/camera_base_link"/>
  <joint name="testing_camera_joint" type="fixed">
    <origin xyz="-0.1 0 0.6" rpy="0 0.4 0"/>
    <parent link="$(arg robot_name)/base_link"/>
    <child link="$(arg robot_name)/camera_base_link"/>
  </joint>


  <!-- pal robotics  _D435  changed values TO _D415 -->
  <!-- https://github.com/pal-robotics/realsense_gazebo_plugin -->
  <xacro:include filename="$(find arlo_gazebo_description)/urdf/_d435.urdf.xacro"/>
  <xacro:sensor_d435 parent="$(arg robot_name)/camera_base_link" 
    use_nominal_extrinsics="true" 
    add_plug="false" 
    use_mesh="true" 
    name="camera" 
    topics_ns="$(arg robot_name)/camera" 
    publish_pointcloud="false"
    update_rate="$(arg update_rate)">
    <origin xyz="0 0 0" rpy="0 0 0"/>
  </xacro:sensor_d435>




</robot>

<!-- 
###################################
############ end ##################
###################################
 -->
  <!-- OG -->
  <!-- <xacro:include filename="$(find realsense2_description)/urdf/_d415.urdf.xacro"/> -->

  <!-- <xacro:arg name="use_nominal_extrinsics" default="true"/>
  <xacro:arg name="add_plug" default="false"/>

  <xacro:sensor_d415 parent="$(arg robot_name)/camera_base_link" use_nominal_extrinsics="true" add_plug="true" name="$(arg robot_name)/camera">
    <origin xyz="0 0 0" rpy="0 0 0"/>

  </xacro:sensor_d415> -->

  <!-- THIS ONE FROM COURSE -->
  <!-- <xacro:include filename="$(find arlo_gazebo_description)/urdf/_d415.urdf.xacro"/>

  <xacro:sensor_d415 parent="$(arg robot_name)/camera_base_link" ns="wx250s" name="camera" updaterate="10" flag_color="1" flag_depth="1" flag_ir="1">
    <origin xyz="0 0.0001 .3" rpy="0 0 0"/>
  </xacro:sensor_d415> -->
  <!-- <joint name="camera_tower" type="fixed">
    <origin rpy="0 0 0" xyz="-0.023997 -0.000044 0.08823"/>
    <parent link="$(arg robot_name)/base_link"/>
    <child link="$(arg robot_name)/camera_tower_link"/>
  </joint>


    <link name="$(arg robot_name)/camera_tower_link">
      <visual>
        <origin rpy="0 0 0" xyz="0 0 0"/>
        <geometry>
          <mesh filename="package://arlo_gazebo_description/meshes/locobot_meshes/locobot_camera_tower_large.stl" scale="0.001 0.001 0.001"/>
        </geometry>
        <material name="interbotix_black"/>
      </visual>
      <collision>
        <origin rpy="0 0 0" xyz="0 0 0"/>
        <geometry>
          <mesh filename="package://arlo_gazebo_description/meshes/locobot_meshes/locobot_camera_tower_large_simple.stl" scale="0.001 0.001 0.001"/>
        </geometry>
      </collision>
      <inertial>
        <origin rpy="0 0 0" xyz="-0.0372211000 -0.0026114300 0.1744600000"/>
        <mass value="2.366224"/>
        <inertia ixx="0.0628500000" ixy="0.0002152000" ixz="0.0065630000" iyy="0.0546000000" iyz="-0.0004738000" izz="0.0179300000"/>
      </inertial>
    </link> -->

   <!-- if arm:=true the include arm_base_joint -->